## 1、函数对象和实例对象

### 1.1 函数对象

- 形如`function Person(){}`中的Person就是函数对象，可以看成通过`new Function()`生成的。

### 1.2 实例对象

- 形如通过`new Person()`产生的对象，称之为实例对象。

## 2、什么是回调

> ==我们定义的，但我们没有调用，最终却执行了==

### 2.1 同步的回调函数

- 理解：==立即在主线程上执行，不会放入回调队列中==

- 例子：数组遍历相关的回调函数

  - ``` js
    let arr = [1,3,5,7,9]
    arr.forEach((item) => {
        console.log(item);
    })
    console.log('a')
    // 输出顺序为 1 3 5 7 9 a
    ```

  - 

### 2.2 异步的回调函数

- 理解：==不会立即执行，会放入回调队列中以后执行==
- 例子：定时器回调/AJAX回调/Promise的成功和失败的回调

## 3、错误处理

### 3.1 错误的类型

- Error：所有错误的父类型

- ReferenceError：引用的变量不存在

  - ``` js
    console.log(a) //未声明变量a，却要输出a的值

- TypeError：数据类型不正确

  - ``` js
    let num = 1;
    num()	//只有函数类型才可以调用
    ```

- RangeError：数据值不在其所允许范围内---==死循环==

  - ``` js
    const demo = () => {demo()}
    demo()
    ```

- SyntaxError：语法错误

  - ``` js
    console.log(1
    ```

### 3.2 错误处理

#### 3.2.1 捕获错误：

- ==try中放可能出现错误的代码，会按顺序执行一旦出现错误立即停止try中代码的执行，调用catch==，并携带错误信息

``` js
try{
 	//自己觉得可能出错的代码   
} catch(error){
    //如果出错了的处理
}

// 例子
try{
    console.log(1)
    console.log(a)
    consoel.log(2)
} catch(error){
    console.log('出错啦')
}

// 输出为：1 '出错啦'
```

#### 3.2.2 抛出错误：

- `throw error`

- ``` js
  throw new Error('出错啦')
  
  function demo(){
      const date = Date.now()
      if(date % 2 === 0){
          console.log('偶数，可以正常工作')
      }else{
          throw new Error('奇数，不可以正常工作')
          // 直接 throw '奇数，不可以正常工作' 也是可以的，但是一般不这样做
      }
  }
  
  try{
      demo()
  } catch(error){
      console.log(error)
  } 
  ```

### 3.3 错误对象

- ==`message`属性==：错误相关信息

- `stack`属性：记录信息

- ``` js
  // 一般使用方式
  try {
      // 可能出错的代码
  } catch(error){
      console.log(error.message) // 打印出错误信息
  }
  ```

- 