## 1、Promise构造函数：==new Promise(executor){}==

- `executor`函数：是同步执行的，`(resolve, reject) => {}`
  - `resolve`函数：调用resolve，会将Promise实例内部状态==改为成功(fulfilled)==
  - `reject`函数：调用reject，会将Promise实例内部状态==改为失败(rejected)==
  - ==这两个函数执行时，只负责马上改变Promise实例对象的状态和抛出值，但并不负责调用.then定义的回调函数，.then定义的回调函数不会马上执行，它是异步函数，要等到同步代码执行完毕后，再执行。同时这两个函数执行并不会阻塞后面代码的执行==
- 说明：`executor`函数会在`Promise`内部==立即同步调用==，==异步代码放在`executor`函数中==

## 2、Promise.prototype.then方法：==Promise实例.then(onFulfilled, onRejected)==

- then方法是绑定在Promise的原型对象上的，供实例对象使用。

- `onFulfilled`：==实例状态为成功时的回调函数==，`(value) => {}`
- `onRejected`：==实例状态为失败时的回调函数==，`(reason) => {}`

- ==特别注意(难点)==：`then`方法会==返回一个新的`Promise`实例对象==

  - ``` js
    let p = new Promise((resolve, reject)=>{
        resolve(1)
    })
    
    let x = p.then(
        (value)=>{console.log('成功了', value)},
    	(error)=>{console.log('失败了', error)}
    )
    ```

  - 

## 3、Promise.prototype.catch方法：==Promise实例.catch(onRejected)==

- catch方法是绑定在Promise的原型对象上的，供实例对象使用。

- `onRejected`：==失败的回调函数==，`(reason) => {}`

- 说明：`catch`方法是`then`方法的语法糖，==相当于：`then(undefined, onRejected)`==

  - ``` js
    const p = new Promise((resolve, reject)=>{
        setTimeout(()=>{
            resolve(-100)
        }, 1000)
    })
    
    p.then(
    	undefined,
        reason => {console.log('失败了1', reason);}
    )
    
    //等价于以下代码
    p.catch(
    	reason => {console.log('失败了', reason);}
    )
    ```

- 几种==特殊情况说明==

  1. ==既定义了`p.then`中的失败回调，也定义了`p.catch`。会两个回调都执行==

     1. ``` js
        const p = new Promise((resolve, reject)=>{
            setTimeout(()=>{
                reject(-100)
            }, 1000)
        })
        
        p.then(
        	undefined,
            reason => {console.log('失败了1', reason);}
        )
        
        p.catch(
        	reason => {console.log('失败了2', reason);}
        )
        ```

  2. Promise回调顺序相关：==Promise实例状态变为`rejected`==，==在`p.then`中只指明成功的回调没有指明失败回调，在`p.catch`中指明了回调==

     1. ``` js
        const p = new Promise((resolve, reject)=>{
            setTimeout(()=>{
                reject(-100)
            }, 1000)
        })
        
        p.then(
            value => {console.log('成功了', value);}
        )
        
        p.catch(
        	reason => {console.log('失败了', reason);}
        )
        ```

     2. ![image-20220807175249206](C:\Users\zayn\AppData\Roaming\Typora\typora-user-images\image-20220807175249206.png)

     3. 这些回调==会被一组一组的压入队列中==，`p.then`没有指明失败的回调，所以`func2`是`undefined`；`p.catch`只用于指明失败的回调，所以`func1`是`undefined`。

     4. ==当实例对象p的状态变成rejected后，会按顺序一组一组的看==。第一组对应`p.then`，==没有指明失败的回调，浏览器报错==。第二组对应`p.catch`，指明了失败的回调，会执行。

     5. 因此浏览器会既有`p.catch`对应的回调函数执行结果，也会有`p.then`导致的报错。

        1. ![image-20220807180358779](C:\Users\zayn\AppData\Roaming\Typora\typora-user-images\image-20220807180358779.png)

  3. Promise回调顺序相关：==Promise实例状态变为`resolved`==，==在`p.then`中未指明成功的回调只指明失败回调，在`p.catch`中指明了回调==

     1. ``` js
        const p = new Promise((resolve, reject)=>{
            setTimeout(()=>{
                resolve(-100)
            }, 1000)
        })
        
        p.then(
            undefined,
            reason => {console.log('失败了', reason);}
        )
        
        p.catch(
        	reason => {console.log('失败了', reason);}
        )
        ```

     2. ![image-20220807180245809](C:\Users\zayn\AppData\Roaming\Typora\typora-user-images\image-20220807180245809.png)

     3. 这些回调==会被一组一组的压入队列中==，`p.then`没有指明成功的回调，所以`func11`是`undefined`；`p.catch`只用于指明失败的回调，所以`func1`是`undefined`。

     4. ==当实例对象p的状态变成resolved后，会按顺序一组一组的看==。第一组对应`p.then`，==没有指明成功的回调，没关系，不会报错，因为成功是一种积极的状态，指不指定回调无所谓==。第二组对应`p.catch`，指明了失败的回调，不会执行。

  4. 总结：

     1. 如果Promise实例状态变为`rejected`，==一定要有对应的回调函数来进行处理，否则会报错==；如果变为`resolved`，==无回调函数处理也可，无所谓==。
     2. ==定义的状态改变后的回调函数会被一组组按顺序压入队列中，Promise实例状态改变后，会按顺序看==。放在实例自身的一个属性中![image-20220807203033300](C:\Users\zayn\AppData\Roaming\Typora\typora-user-images\image-20220807203033300.png)

## 4、Promise.resolve方法：==Promise.resolve(value)==

- 说明：用于快速==返回一个状态为`fulfilled`或`rejected`的`Promise`实例对象==。（如果没有这个方法，想得到一个状态为`fulfilled`的`Promise`实例对象，得先`new Promise`，然后在回调函数里`resolve(xxx)`）

- `value`的值可能是：(1)非`Promise`值（2）`Promise`值

  1. 非`Promise`值：例如字符串、数组等等，那么返回的一定是`fulfilled`状态的实例对象

  2. ==Promise值==：

     1. 如果`value`是状态为`fulfilled`的实例对象，那么最终返回的一定是`fulfilled`状态的实例对象

        - ``` js
                let p0 = Promise.resolve(100);
                let p = Promise.resolve(p0);
            
                p.then(
                  (value) => {
                    console.log("成功了", value);
                  },
                  (reason) => {
                    console.log("失败了", reason);
                  }
                );
          // 最终输出 "成功了"100
          ```

     2. ==如果`value`是状态为`rejected`的实例对象，那么最终返回的一定是`rejected`状态的实例对象==

        - ``` js
                let p0 = Promise.reject(-100);
                let p = Promise.resolve(p0);
            
                p.then(
                  (value) => {
                    console.log("成功了", value);
                  },
                  (reason) => {
                    console.log("失败了", reason);
                  }
                );
          // 最终输出 "失败了"-100
          ```

        - 

## 5、Promise.reject方法：==Promise.reject(reason)==

- 说明：用于快速==返回一个状态必为`rejected`的Promise实例对象==

- `reason`的值可能是：(1)非`Promise`值（2）`Promise`值

  1. 非`Promise`值：例如字符串、数组等等，那么返回的一定是`rejected`状态的实例对象

  2. ==Promise值==：

     1. 如果`value`是状态为`fulfilled`的实例对象，那么最终返回的一定是`rejected`状态的实例对象

        - ``` js
                let p0 = Promise.resolve(100);
                let p = Promise.reject(p0);
            
                p.then(
                  (value) => {
                    console.log("成功了", value);
                  },
                  (reason) => {
                    console.log("失败了", reason);
                  }
                );
          // 最终输出 "失败了" Promise对象
          ```

     2. 如果`value`是状态为`rejecteded`的实例对象，那么最终返回的一定是`rejected`状态的实例对象。注意以下代码未指定失败的回调，在浏览器运行时会报错

        - ``` js
                let p0 = Promise.reject(100);
                let p = Promise.reject(p0);
            
                p.then(
                  (value) => {
                    console.log("成功了", value);
                  },
                  (reason) => {
                    console.log("失败了", reason);
                  }
                );
          // 最终输出 "失败了" Promise对象
          ```

        - 

## 6、Promise.all方法：==Promise.all(promiseArr)==

- `promiseArr`：==包含n个Promise实例的数组==

- 说明：==返回一个新的Promise实例==，只有==数组里所有的Promise实例都成功，该新Promise实例才成功，只要数组中有一个失败了，就会失败==。

- 可能出现的情况

  1. ==数组中的实例最终都是成功状态==

     1. ==新Promise实例最终也为成功状态==，`value`是==由所有数组中的Promise实例成功状态的value组成的数组，该数组的顺序和promiseArr的顺序一致==

     2. ``` js
              const p1 = Promise.resolve("a");
              const p2 = new Promise((resolve, reject) => {
                setTimeout(() => {
                  resolve("b");
                }, 500);
              });
              const p3 = new Promise((resolve, reject) => {
                setTimeout(() => {
                  resolve("c");
                }, 2000);
              });
           
              const p = Promise.all([p1, p3, p2]);
              p.then(
                (value) => {
                  console.log("成功了", value);
                },
                (reason) => {
                  console.log("失败了", reason);
                }
              );
        // 最终输出的是 “成功了”,['a','c','b'];
        // 可以看到p2是变为成功状态更快的实例，但是最终p接收到的value的顺序，仍然是按照Promise.all参数的数组的顺序来的。与变为成功状态的速度无关
        ```

     3. 

  2. 数组中的实例==至少有一个是失败状态==

     1. ==新Promise实例最终是失败==，`reason`是==数组中最快变为失败状态的`Promise`实例发出的的`reason`==

        1. ``` js
                 const p1 = Promise.resolve("a");
                 const p2 = new Promise((resolve, reject) => {
                   setTimeout(() => {
                     reject("b");
                   }, 500);
                 });
                 const p3 = new Promise((resolve, reject) => {
                   setTimeout(() => {
                     reject("c");
                   }, 2000);
                 });
              
                 const p = Promise.all([p1, p3, p2]);
                 p.then(
                   (value) => {
                     console.log("成功了", value);
                   },
                   (reason) => {
                     console.log("失败了", reason);
                   }
                 );
              
           // 最终的输出是 "失败了",b
           // 可以看到，尽管promiseArr里的顺序是p3在前面，但是它变为失败的状态没有p2快，所以失败的结果与数组顺序无关，谁先失败，谁就终止这个新实例。
           ```


## 7、Promise.race方法：==Promise.race(promiseArr)

- `promiseArr`：包含n个Promise实例的数组
- 说明：返回一个新的Promise实例，==成功还是失败，以最先出结果的promise实例为准。==

- 可能出现的情况：

  1. 成功的promise更快

     1. ``` js
              const p1 = Promise.resolve("a");
              const p2 = new Promise((resolve, reject) => {
                setTimeout(() => {
                  reject("b");
                }, 500);
              });
              const p3 = new Promise((resolve, reject) => {
                setTimeout(() => {
                  reject("c");
                }, 2000);
              });
           
              const p = Promise.race([p1, p3, p2]);
              p.then(
                (value) => {
                  console.log("成功了", value);
                },
                (reason) => {
                  console.log("失败了", reason);
                }
              );
           
        // 最终输出 "成功了" 'a'
        ```

  2. 失败的promise更快

     1. ``` js
              const p1 = Promise.reject("a");
              const p2 = new Promise((resolve, reject) => {
                setTimeout(() => {
                  resolve("b");
                }, 500);
              });
              const p3 = new Promise((resolve, reject) => {
                setTimeout(() => {
                  resolve("c");
                }, 2000);
              });
           
              const p = Promise.race([p1, p3, p2]);
              p.then(
                (value) => {
                  console.log("成功了", value);
                },
                (reason) => {
                  console.log("失败了", reason);
                }
              );
           
        //输出 "失败了" a
        ```

     2. 