## 1、语法

``` js
async function (){
    const result = await p
}
```

1. `async` 修饰的函数
   1. 函数的==返回值为`Promise`对象==
   2. `Promise`实例的结果由`async`函数执行的返回值决定

      - ==`return`非`Promise`值==：最终函数的返回的Promise对象==状态一定是成功==的，==value是该非`Promise`值==

        - ``` js
                async function demo() {
                  return 1;
                }
                let b = demo();
                b.then(
                  (value) => {
                    console.log("成功了", value);
                  },
                  (error) => {
                    console.log("失败了", error);
                  }
          ```

      - `return Promise实例对象`：最终==函数返回的`Promise`对象就是该`Promise`实例对象==

        - ``` js
                async function demo() {
                  return Promise.reject(-100);
                }
                let b = demo();
                b.then(
                  (value) => {
                    console.log("成功了", value);
                  },
                  (error) => {
                    console.log("失败了", error);
                  }
                );
          ```

        - 
2. `await`表达式

   1. `await`右侧的表达式一般为`Promise实例对象`，但也可以是其它的值
      - 如果表达式是==`Promise`实例对象==，==`await`后的返回值时`Promise`成功的值==
      - 如果表达式是==其它值==，直接将此值作为`await`的返回值

3. 注意：

   1. ==`await`必须写在`async`函数中==，但`async`函数中可以没有await(不使用await，定义`async`函数并没有什么意义)

      - ![image-20220809164241528](C:\Users\zayn\AppData\Roaming\Typora\typora-user-images\image-20220809164241528.png)

   2. ==如果`await`的`Promsie`实例对象失败了，就会抛出异常，需要通过`try...catch`来捕获处理==

      - `try catch`一定要精确地放到可能抛出错误的那一段代码。
      - <img src="C:\Users\zayn\AppData\Roaming\Typora\typora-user-images\image-20220809164314983.png" alt="image-20220809164314983" style="zoom:67%;" />
      - 例如像以下代码是捕捉不到错误的,`try catch`一定要精准的放到出错的作用域里。
        - ![image-20220809171710354](C:\Users\zayn\AppData\Roaming\Typora\typora-user-images\image-20220809171710354.png)

   3. 一般情况下，不会定义`async`函数，然后再调用。直接用==立即执行函数==

      - ``` js
              const p = () => {
                return new Promise((resolve, reject) => {
                  resolve(1);
                });
              };
              (async function () {
                const result = await p();
                console.log(result);
              })();
        ```

      - 立即执行函数有个小bug，那就是==上一行代码必须要有分号==或者自己添加感叹号

        - <img src="C:\Users\zayn\AppData\Roaming\Typora\typora-user-images\image-20220809200520453.png" alt="image-20220809200520453" style="zoom:67%;" />
        - <img src="C:\Users\zayn\AppData\Roaming\Typora\typora-user-images\image-20220809200903771.png" alt="image-20220809200903771" style="zoom:67%;" />

      

## 2、==实现链式调用==

- 第二个请求依赖于第一个请求，在第一个请求完成的情况下，发送第二个请求。第三个请求依赖于第二个请求，在第二个请求完成的情况下，发送第三个请求

- `await`实际上是`async wait`，等到==右侧的Promise状态变为成功的时候才会继续往下执行==。

- ``` js
        const p1 = () => Promise.resolve(100);
        const p2 = () => Promise.reject(-1);
        const p3 = () => Promise.resolve(200);
    
        (async function () {
          try {
            const res1 = await p1();
            console.log("第一次成功了", res1);
            const res2 = await p2();
            console.log("第二次成功了", res2);
            const res3 = await p3();
            console.log("第三次成功了", res3);
          } catch (error) {
            console.log("出错了", error);
          }
        })();
    
        (async function () {
          try {
            const res1 = await sendAjax('http://localhost:3000/users/get_req', {});
            console.log("第一次请求成功了", res1);
            const res2 = await sendAjax('http://localhost:3000/users/get_req', {});
            console.log("第二次请求成功了", res2);
            const res3 = await sendAjax('http://localhost:3000/users/get_req', {});
            console.log("第三次请求成功了", res3);
          } catch (error) {
            console.log("出错了", error);
          }
        })();

## 3、原理

若我们使用`async`配合`await`这种写法：

- 表面上不出现任何的回调函数
- 但实际上==底层把我们写的代码进行了加工，把回调函数"还原"回来了==。
- 最终运行的代码时依然有回调的，只是程序员没有看见

以下述代码为例：(下述代码不符合规范，但是方便理解)

  ```js
const p = new Promise((resolve, reject) => {
    setTimeout(()=>{
        resolve('a');
        console.log(b)
    }, 4000)
});

async function demo(){
    const result = await p;
    console.log(result);
    console.log(100);
    console.log(200);
}
demo()
console.log('代码全部结束啦！')
  ```

- 首先解释不符合规范的原因，==即使不执行`demo`函数==，在`new Promise(executor)`的时候，就会立马执行`executor`函数，从而开启定时器，在4s后将回调压入异步队列中，最终回调会被执行，改变了对象实例p的状态。那么在`async`函数里写的`await p `就没有意义，不需要你等，它自己马上就执行完了，不符合逻辑
- 按理说：要等`demo()`函数执行完毕了，才执行`console.log('代码全部结束啦！')`，按照常理的执行顺序应当是
  - `console.log(result) console.log(100) console.log(200) console.log('代码全部结束啦！')`
- 但实际上的执行顺序是
  - `console.log('代码全部结束啦！') console.log(result) console.log(100) console.log(200)` 

原理：==底层在发现`await p`后会把代码翻译成以下形式==

- ``` js
  const p = new Promise((resolve, reject) => {
      setTimeout(()=>{
          resolve('a');
          console.log(b)
      }, 4000)
  });
  
  async function demo(){
  	p.then(
          (result)=>{
          	console.log(result);
              console.log(100);
              console.log(200);
          }
      )
  }
  demo()
  console.log('代码全部结束啦！')
  ```

- 这样也就是快速定义了实例对象`p`状态为成功时的回调函数，那么demo这个函数就执行完毕了，紧接着就执行了同步代码`console.log('代码全部结束啦！')`。同步代码执行完毕后，执行异步任务定时器的回调，改变了实例对象`p`的状态为成功，进而执行成功状态的回调，`console.log(result) console.log(100) console.log(200)`

  - <img src="C:\Users\zayn\AppData\Roaming\Typora\typora-user-images\image-20220809214651190.png" alt="image-20220809214651190" style="zoom:67%;" />

## 4、==注意事项==

类似于

``` js
const p = new Promise((resolve, reject)=>{
    resolve('a')
});

async function demo(){
    const result = await p;
    console.log(result);
}
demo()
```

- 以上代码是不符合逻辑的，因为在`async`函数内部，还在`await p`之前，实例`p`的`executor`函数在new的时候已经执行了，那么`await p`就没有意义了。应当是直到`await p`时，再执行`p`的`executor`函数。

特别是对于以下代码，不符合逻辑的地方更明显

``` js
const p = new Promise((resolve, reject)=>{
    reject('b');
});

try{
    (async function(){
        const result = await p;
        console.log(result);
    })()
} catch(error){
 	console.log('出错啦', error)   
}
```

- `try catch`根本捕捉不到错误，因为在`cosnt p = new Promsie(executor) `这里，会直接运行`executor`函数，然后就会抛出了错误。

改成下列才是合理的

``` js
const p = () =>{
    return new Promise((resolve, reject)=>{
    	reject('b');
	});
}

try{
    (async function(){
        const result = await p();
        console.log(result);
    })()
} catch(error){
 	console.log('出错啦', error)   
}
```

- `const  p= ()=> new Promise(exevutor)`定义了一个函数，函数的返回值是一个Promise实例，此时==函数p只是定义了，并没有执行，所以`executor`函数并没有执行。直到`const result = await p()`明确调用了`p`函数，`p`函数才执行，因此`executor`函数才执行，才会抛出错误==。并且返回的是一个Promise实例，也符合`await Promise实例 `的要求。